!Command
command:
- deepnog
positional: []
named: []
parent:
subcommands: []
usage: []
help_flag:
usage_flag:
version_flag:
help_text: "Traceback (most recent call last):\n  File \"/usr/local/lib/python3.8/site-packages/deepnog/utils/imports.py\"\
  , line 14, in try_import_pytorch\n    import torch\nModuleNotFoundError: No module\
  \ named 'torch'\n\nThe above exception was the direct cause of the following exception:\n\
  \nTraceback (most recent call last):\n  File \"/usr/local/bin/deepnog\", line 6,\
  \ in <module>\n    from deepnog.client import main\n  File \"/usr/local/lib/python3.8/site-packages/deepnog/client/__init__.py\"\
  , line 1, in <module>\n    from .client import main\n  File \"/usr/local/lib/python3.8/site-packages/deepnog/client/client.py\"\
  , line 45, in <module>\n    from deepnog.utils.config import get_config\n  File\
  \ \"/usr/local/lib/python3.8/site-packages/deepnog/utils/__init__.py\", line 4,\
  \ in <module>\n    from .io_utils import create_df, get_data_home, get_weights_path\n\
  \  File \"/usr/local/lib/python3.8/site-packages/deepnog/utils/io_utils.py\", line\
  \ 25, in <module>\n    torch = try_import_pytorch()\n  File \"/usr/local/lib/python3.8/site-packages/deepnog/utils/imports.py\"\
  , line 20, in try_import_pytorch\n    raise ImportError(msg) from e\nImportError:\
  \ \nIf deepnog was installed via bioconda,please install its requirement pytorch\
  \ with:\n$ conda install pytorch -c pytorch\n"
generated_using:
- --help
docker_image: quay.io/biocontainers/deepnog:1.2.3--pyh5bfb8f1_0
