!Command
command:
- pyomo_nsc
positional:
- !Positional
  optional: false
  position: 0
  name: '@_call_aside'
  description: File "/usr/local/lib/python3.4/site-packages/pkg_resources/__init__.py",
    line 2962, in _call_aside
named: []
parent:
subcommands: []
usage: []
help_flag:
usage_flag:
version_flag:
help_text: "Traceback (most recent call last):\n  File \"/usr/local/lib/python3.4/site-packages/pkg_resources/__init__.py\"\
  , line 660, in _build_master\n    ws.require(__requires__)\n  File \"/usr/local/lib/python3.4/site-packages/pkg_resources/__init__.py\"\
  , line 968, in require\n    needed = self.resolve(parse_requirements(requirements))\n\
  \  File \"/usr/local/lib/python3.4/site-packages/pkg_resources/__init__.py\", line\
  \ 859, in resolve\n    raise VersionConflict(dist, req).with_context(dependent_req)\n\
  pkg_resources.ContextualVersionConflict: (PyUtilib 5.4 (/usr/local/lib/python3.4/site-packages),\
  \ Requirement.parse('PyUtilib==5.1.3556'), {'Pyomo'})\n\nDuring handling of the\
  \ above exception, another exception occurred:\n\nTraceback (most recent call last):\n\
  \  File \"/usr/local/bin/pyomo_nsc\", line 5, in <module>\n    from pkg_resources\
  \ import load_entry_point\n  File \"/usr/local/lib/python3.4/site-packages/pkg_resources/__init__.py\"\
  , line 2976, in <module>\n    @_call_aside\n  File \"/usr/local/lib/python3.4/site-packages/pkg_resources/__init__.py\"\
  , line 2962, in _call_aside\n    f(*args, **kwargs)\n  File \"/usr/local/lib/python3.4/site-packages/pkg_resources/__init__.py\"\
  , line 2989, in _initialize_master_working_set\n    working_set = WorkingSet._build_master()\n\
  \  File \"/usr/local/lib/python3.4/site-packages/pkg_resources/__init__.py\", line\
  \ 662, in _build_master\n    return cls._build_from_requirements(__requires__)\n\
  \  File \"/usr/local/lib/python3.4/site-packages/pkg_resources/__init__.py\", line\
  \ 675, in _build_from_requirements\n    dists = ws.resolve(reqs, Environment())\n\
  \  File \"/usr/local/lib/python3.4/site-packages/pkg_resources/__init__.py\", line\
  \ 854, in resolve\n    raise DistributionNotFound(req, requirers)\npkg_resources.DistributionNotFound:\
  \ The 'PyUtilib==5.1.3556' distribution was not found and is required by Pyomo\n"
generated_using:
- --help
docker_image:
